Workbook

Sheet Tax rules
B2: Income Tax Software 2019 - 20 ( Calculator )
B3: For update Income Tax software visit my website www.teacherNews.in
B4: Financial year 2019- 20 | Assessment Year 2020 -21
C5: Follow theTax Rules & Informations (where applicable). Following linked ready reaconer is for your reference.
B6: 1 | C6: New Tax Rates for Financial-Year 2019-20, Assessment Year 2020-2021
B7: 2 | C7: Some Exempted Receipts / Special allowances & Perquisite which are not chargable to tax
B8: 2 | C8: Some Exempted Income ( to be shown while Return filing)
C10: T A X R U L E S & O T H E R U S E F U L I N F O R M A T I O N S
B11: I | C11: HRA exemption
B12: II | C12: Transport allowance
B13: III | C13: Reimbursement of Medical bills
B14: IV | C14: u/s(5) LTA is exempt
B15: IV | C15: u/s 24 Exemption for interest on housing loan.
B16: V | C16: u/s 80CCE & 80CCD Maximum Exemption
B17: VI | C17: u/s 80 CCG Rajiv Gandhi Equity Savings Scheme
B18: VII | C18: u/s 80D Medical Insurance
B19: VIII | C19: u/s 80DD Deduction in respect of medical treatment of handicapped dependents
B20: IX | C20: u/s 80DDB Deduction in respect of medical treatment for specified ailments or diseases
B21: X | C21: u/s 80E Interest repayment on education loan
B22: XI | C22: u/s 80G Donations given for certain charities
... B25: XIV | C25: u/s 80TTA Deduction on interest on saving bank accounts.
C26: KNOW MORE about DEDUCTION under Section 80-C
B27: a | C27: Qualifying Investments u/s 80CCE
B28: b | C28: Provident Fund (PF) & Voluntary Provident Fund (VPF)
B29: c | C29: Life Insurance Premiums & Unit linked Insurance Plan (ULIP)
B30: d | C30: Public Provident Fund (PPF):
B31: e | C31: National Savings Certificate (NSC):
B32: f | C32: Home Loan Principal Repayment & Stamp Duty and Registration Charges for a home
B33: g | C33: Tuition fees for 2 children
B34: h | C34: Equity Linked Savings Scheme (ELSS)
B35: i | C35: 5-Yr bank fixed deposits (FDs) or 5-Yr post office time deposit (POTD)
B36: j | C36: Pension Funds or Pension Policies
B37: k | C37: Stamp Duty and Registration Charges for a home:
B38: l | C38: Infrastructure Bonds: NABARD rural bonds:
B39: m | C39: Senior Citizen Savings Scheme 2004 (SCSS)
B40: 6 | C40: I M P O R T A N T - A D V I S ES
C41: TAX RATES For Financial Year 2019-20 & Assesment Year 2020 -21
C42: For MALE/FEMALE ASSESSE
C43: Net Income Range Income Tax Rates
C44: Up to Rs.2,50,000 Nil
...

Sheet DATA
X2: DA Arrears
B4: Mobile Income Tax Software | H4: Jul 2018 DA Arrears Online Calculator | M4: Jul 2018 DA Arrears Calculator | Q4: =IF(S11<5000,"You Need Not Submit Rent Receipt for this rent.",IF(AND(S11>5000,S11<8300)," You Should Submit Rent Receipt with Out Owner PAN Number.",IF(S11<83000," You Should Submit Rent Receipt with PAN No. of House Owner."))) -> You Should Submit Rent Receipt with PAN No. of House Owner. | X4: Jul 2018 DA Arrears Taken
X5: Jan 2019 DA Arrears Taken
X6: AAS Taken (07/2018 to 12/2020)
B7: C.Ramanjaneyulu Income Tax Software 2021-22 for AP Teachers & Employees | Y7: July 2018 DA Arrears | AB7: Jan 2019 DA Arrears
C9: Employee & DDO Details | J9: Select Regime | N9: Basic Pay & Benefits | S9: House Rent | X9: =AY144 -> 43282 | Y9: =AW144 -> 19500 | Z9: =IF(X9=AT$189,AT$194,BA144) -> 613
C10: Employee Name | E10: A.Nagesh | J10: Allowances Details | N10: Basic Pay January - 2021 | X10: =AY145 -> 43313 | Y10: =AW145 -> 20050 | Z10: =IF(X10=AT$189,AT$194,BA145) -> 631 | AN10: =(SUM(Z9:Z16)+SUM(AC15:AC16)) -> 6290 | AO10: =IF(CL$274=1,"( DA Arrears FY 2018-19 )","") -> ( DA Arrears FY 2018-19 )
C11: Designation | E11: Deputy Executive Engineer | J11: HRA on Mar - 2021 | N11: Increment Month | S11: 12000 | X11: =AY146 -> 43344 | Y11: =AW146 -> 20050 | Z11: =IF(X11=AT$189,AT$194,BA146) -> 631
C12: Employees PAN No. | J12: Change HRA | N12: AAS Increment | S12: Net Tax | X12: =AY147 -> 43374 | Y12: =AW147 -> 20050 | Z12: =IF(X12=AT$189,AT$194,BA147) -> 631
C13: School/Office | E13: Executive Engineer,TGP Division No.1 | J13: HM Allowance | N13: Promotion | S13: =IF('Annexure -I I'!J67='Annexure -I I'!Q69,"",CONCATENATE("Rs. ",'Annexure -I I'!L67)) -> Rs. 42996 | X13: =AY148 -> 43405 | Y13: =AW148 -> 20050 | Z13: =IF(X13=AT$189,AT$194,BA148) -> 631
C14: Working Place | E14: Velgode | J14: PH Allowance | N14: Surrender leave (2021-22) | S14: Total Saving | X14: =AY149 -> 43435 | Y14: =AW149 -> 20050 | Z14: =IF(X14=AT$189,AT$194,BA149) -> 631
C15: Mandal | E15: Velgode | J15: Edu. Concession | N15: Surrender Leave with Pay, DA, HRA | S15: ='Annexure -I I'!L46 -> 150000 | X15: =AY150 -> 43466 | Y15: =AW150 -> 20050 | Z15: =IF(X15=AT$189,AT$194,BA150) -> 631 | AB15: =AW150 -> 20050 | AC15: =IF(X15=AT$189,AT$197,BC150) -> 630
C16: District | E16: Kurnool | J16: Rented / Own House | N16: Half Pay Leave | X16: =AY151 -> 43497 | Y16: =AW151 -> 20050 | Z16: =IF(X16=AT$189,AT$194,BA151) -> 631 | AB16: =AW151 -> 20050 | AC16: =IF(X16=AT$189,AT$197,BC151) -> 630
C17: Vacation / Non Vacation | J17: Select PF/CPS | N17: Without DA in HRA Calculation | Q17: w | X17: =AY152 -> 43525 | Y17: =AW152 -> 20050 | Z17: =IF(X17=AT$189,AT$194,BA152) -> 631 | AB17: =AW152 -> 20050 | AC17: =IF(X17=AT$189,AT$197,BC152) -> 630
C18: Treasury Id No. | J18: Additional HRA | X18: =AY153 -> 43556 | Y18: =AW153 -> 20050 | Z18: =IF(X18=AT$189,AT$194,BA153) -> 631 | AB18: =AW153 -> 20050 | AC18: =IF(X18=AT$189,AT$197,BC153) -> 630
C19: DDO Name | E19: N.C.Subbarayudu | N19: Employee Salary Deductions | X19: =AY154 -> 43586 | Y19: =AW154 -> 20050 | Z19: =IF(X19=AT$189,AT$194,BA154) -> 631 | AB19: =AW154 -> 20050 | AC19: =IF(X19=AT$189,AT$197,BC154) -> 630
C20: Disignation | E20: Executive Engineer,TGP Division No.1 | J20: CCA Recived Monthly | N20: PF Monthly | P20: 7000 | Q20: PF Change | X20: =AY155 -> 43617 | Y20: =AW155 -> 20050 | Z20: =IF(X20=AT$189,AT$194,BA155) -> 631 | AB20: =AW155 -> 20050 | AC20: =IF(X20=AT$189,AT$197,BC155) -> 630
C21: DDO Office & Place | E21: Velgode | J21: SCA | N21: =IF(CL274=1,"APGLI Mothly ","TSGLI Mothly ") -> APGLI Mothly | P21: 2000 | Q21: =IF(CL274=1," APGLI Change","TSGLI Change") -> APGLI Change | X21: =AY156 -> 43647 | Y21: =AW156 -> 20050 | Z21: =IF(X21=AT$189,AT$194,BA156) -> 631 | AB21: =AW156 -> 20050 | AC21: =IF(X21=AT$189,AT$197,BC156) -> 630 | AN21: =SUM(Z17:Z28)+SUM(AC17:AC28) -> 15391 | AO21: ( DA Arrears FY 2019-20 )
C22: Mandal | E22: Velgode | J22: HRA Under Taking | N22: GIS Monthly | P22: 120 | Q22: GIS Change | X22: =AY157 -> 43678 | Y22: =AW157 -> 20640 | Z22: =IF(X22=AT$189,AT$194,BA157) -> 649 | AB22: =AW157 -> 20640 | AC22: =IF(X22=AT$189,AT$197,BC157) -> 649
C23: DDO PAN | E23: TAN | J23: PP/SP/Addl. Inc. | N23: PF/CPS No | Q23: =IF(CL274=1,"APGLI No","TSGLI No") -> APGLI No | X23: =AY158 -> 43709 | Y23: =AW158 -> 20640 | Z23: =IF(X23=AT$189,AT$194,BA158) -> 649 | AB23: =AW158 -> 20640 | AC23: =IF(X23=AT$189,AT$197,BC158) -> 649
J24: =IF(CL274=2,"TS Increment","") | N24: LIC Paid Monthly in Salary | Q24: LIC Change | X24: =AY159 -> 43739 | Y24: =AW159 -> 20640 | Z24: =IF(X24=AT$189,AT$194,BA159) -> 649 | AB24: =AW159 -> 20640 | AC24: =IF(X24=AT$189,AT$197,BC159) -> 649
C25: Savings | J25: Update IT Software Available at www.teacherNews.in | N25: EWF (March 2021) | P25: 50 | Q25: SWF (December 2021) | X25: =AY160 -> 43770 | Y25: =AW160 -> 20640 | Z25: =IF(X25=AT$189,AT$194,BA160) -> 649 | AB25: =AW160 -> 20640 | AC25: =IF(X25=AT$189,AT$197,BC160) -> 649
N26: Salary Health Insurance | Q26: If Change | X26: =AY161 -> 43800 | Y26: =AW161 -> 20640 | Z26: =IF(X26=AT$189,AT$194,BA161) -> 649 | AB26: =AW161 -> 20640 | AC26: =IF(X26=AT$189,AT$197,BC161) -> 649
X27: =AY162 -> 43831 | Y27: =AW162 -> 20640 | Z27: =IF(X27=AT$189,AT$194,BA162) -> 649 | AB27: =AW162 -> 20640 | AC27: =IF(X27=AT$189,AT$197,BC162) -> 649
N28: Advance Tax Paid | X28: =AY163 -> 43862 | Y28: =AW163 -> 20640 | Z28: =IF(X28=AT$189,AT$194,BA163) -> 649 | AB28: =AW163 -> 20640 | AC28: =IF(X28=AT$189,AT$197,BC163) -> 649
N29: 44256 | O29: 8000 | P29: 44378 | Q29: 8000 | S29: 44501 | T29: 8000 | X29: =AY164 -> 43891 | Y29: =AW164 -> 20640 | Z29: =IF(X29=AT$189,AT$194,BA164) -> 649 | AB29: =AW164 -> 20640 | AC29: =IF(X29=AT$189,AT$197,BC164) -> 649
N30: 44287 | O30: 8000 | P30: 44409 | Q30: 8000 | S30: 44531 | T30: 20000 | X30: =AY165 -> 43922 | Y30: =AW165 -> 20640 | Z30: =IF(X30=AT$189,AT$194,BA165) -> 649 | AB30: =AW165 -> 20640 | AC30: =IF(X30=AT$189,AT$197,BC165) -> 649
N31: 44317 | O31: 8000 | P31: 44440 | Q31: 8000 | S31: 44562 | X31: =AY166 -> 43952 | Y31: =AW166 -> 20640 | Z31: =IF(X31=AT$189,AT$194,BA166) -> 649 | AB31: =AW166 -> 20640 | AC31: =IF(X31=AT$189,AT$197,BC166) -> 649
C32: Tax Deductions | N32: 44348 | O32: 8000 | P32: 44470 | Q32: 8000 | S32: 44593 | X32: =AY167 -> 43983 | Y32: =AW167 -> 20640 | Z32: =IF(X32=AT$189,AT$194,BA167) -> 649 | AB32: =AW167 -> 20640 | AC32: =IF(X32=AT$189,AT$197,BC167) -> 649
X33: =AY168 -> 44013 | Y33: =AW168 -> 20640 | Z33: =IF(X33=AT$189,AT$194,BA168) -> 649 | AB33: =AW168 -> 20640 | AC33: =IF(X33=AT$189,AT$197,BC168) -> 649
C34: Deductions for disabled(blind,PH) person (40%) | X34: =AY169 -> 44044 | Y34: =AW169 -> 21230 | Z34: =IF(X34=AT$189,AT$194,BA169) -> 667 | AB34: =AW169 -> 21230 | AC34: =IF(X34=AT$189,AT$197,BC169) -> 668 | AN34: =SUM(Z29:Z38)+SUM(AC29:AC40) -> 14501 | AO34: ( DA Arrears FY 2020-21 )
X35: =AY170 -> 44075 | Y35: =AW170 -> 21230 | Z35: =IF(X35=AT$189,AT$194,BA170) -> 667 | AB35: =AW170 -> 21230 | AC35: =IF(X35=AT$189,AT$197,BC170) -> 668
X36: =AY171 -> 44105 | Y36: =AW171 -> 21230 | Z36: =IF(X36=AT$189,AT$194,BA171) -> 667 | AB36: =AW171 -> 21230 | AC36: =IF(X36=AT$189,AT$197,BC171) -> 668
C37: National Pension Scheme U/s 80CCD (1B) | N37: Loss or Income from House property select (U/s 24) | X37: =AY172 -> 44136 | Y37: =AW172 -> 21230 | Z37: =IF(X37=AT$189,AT$194,BA172) -> 667 | AB37: =AW172 -> 21230 | AC37: =IF(X37=AT$189,AT$197,BC172) -> 668
J38: Other Sources Income | N38: Rent received during the Year | X38: =AY173 -> 44166 | Y38: =AW173 -> 21230 | Z38: =IF(X38=AT$189,AT$194,BA173) -> 667 | AB38: =AW173 -> 21230 | AC38: =IF(X38=AT$189,AT$197,BC173) -> 668
N39: Muncipal Tax Paid | X39: =AY174 -> 44197 | Y39: =AW174 -> 21230 | AB39: =AW174 -> 21230 | AC39: =IF(X39=AT$189,AT$197,BC174) -> 668
C40: C.Ramanjaneyulu, S.A( P.S ) | N40: 30% of Income as Maintenance | Q40: =IF(DATA!BQ238=1,DATA!BM236,"") | X40: =AY175 -> 44228 | Y40: =AW175 -> 21230 | AB40: =AW175 -> 21230 | AC40: =IF(X40=AT$189,AT$197,BC175) -> 668
C41: Please Don't Call School Hours | G41: Contact : 9160840947 | N41: =BN239&" from Housing Property" -> Income from Housing Property | Q41: =BM239 | X41: =AY176 -> 44256 | Y41: =AW176 -> 21230 | AB41: =AW176 -> 21230 | AC41: =IF(X41=AT$189,AT$197,BC176) -> 668
X42: =AY177 -> 44287 | Y42: =AW177 -> 21230 | AB42: =AW176 -> 21230 | AC42: =IF(X42=AT$189,AT$197,BC177) -> 668
C43: DA & Other Arrears ( Exmption 10E) | N43: House Address for Rent Reciept | X43: =AY178 -> 44317 | Y43: =AW178 -> 21230 | AB43: =AW178 -> 21230 | AC43: =IF(X43=AT$189,AT$197,BC178) -> 668 | AN43: =SUM(AC41:AC44) -> 2672 | AO43: ( DA Arrears FY 2021-22 )
...

Sheet Bill
X2: =IF(DATA!CL274=1,"Select","") -> Select | Y2: =IF(DATA!CL274=1,"If You want to One or Two DA Arrears","") -> If You want to One or Two DA Arrears | AH2: Two
B4: =CONCATENATE(" Month wise Income of ",DATA!BN172," ",DATA!E10,", ",DATA!CD169,", ",DATA!E13," , ",DATA!E14,", ",DATA!E15," (","Mandal",")"," for the year of 2021-22") -> Month wise Income of Sri. A.Nagesh, Deputy Executive Engineer, Executive Engineer,TGP Division No.1 , Velgode, Velgode (Mandal) for the year of 2021-22
B6: S.No | C6: Month & Year | D6: Pay | E6: DA | F6: IR | G6: HRA | H6: =IF(DATA!CL274=2,"TS. Inc.","IR") -> IR | I6: =H6 -> IR | J6: HM Allowance | K6: =J6 -> HM Allowance | L6: SP/PP/Add. Inc. | M6: =L6 -> SP/PP/Add. Inc. | N6: A HRA | O6: =N6 -> A HRA | P6: DA Arrears | Q6: =P6 -> DA Arrears | R6: PHA | S6: =R6 -> PHA | T6: CCA | U6: =T6 -> CCA | V6: SCA | W6: =V6 -> SCA | X6: Gross Total | Y6: =DATA!CE184 -> PF | Z6: =Y6 -> PF | AA6: APGLI | AB6: =AA6 -> APGLI | AC6: P.Tax | AD6: GIS | AE6: =AD6 -> GIS | AF6: SWF/ EWF/ CMRF | AG6: EHF Deduction | AH6: Salary LIC | AI6: Adavance Tax | AJ6: Total Deduction | AK6: Net Amount | AL6: DA %
B7: 1 | C7: 44256 | D7: 55410 | E7: 16840 | G7: 6649 | H7: =IF(DATA!CR$273=2,IF(DATA!CL$274=2,DATA!L$24,DATA!CL283),ROUND(IF(DATA!CL$274=2,DATA!L$24,DATA!CL283)/2,0)) -> 5732 | I7: 14961 | J7: =IF(DATA!CR$273=2,DATA!L$13,ROUND(DATA!L$13/2,0)) -> 0 | K7: =IF(J7=0,"",J7) | L7: =IF(DATA!CR$273=2,DATA!CH283,ROUND(DATA!CH283/2,0)) -> 0 | M7: =IF(L7=0,"",L7) | N7: =IF(DATA!CR$273=2,DATA!CZ283,ROUND(DATA!CZ283/2,0)) -> 0 | O7: =IF(N7=0,"",N7) | R7: =IF(DATA!CR$273=2,DATA!CJ283,ROUND(DATA!CJ283/2,0)) -> 0 | S7: =IF(R7=0,"",R7) | T7: =IF(DATA!CR$273=2,IF(DATA!DK178=0,0,DATA!DK178),ROUND(IF(DATA!DK178=0,0,DATA!DK178)/2,0)) -> 0 | U7: =IF(T7=0,"",T7) | V7: =IF(DATA!CR$273=2,DATA!DF162,ROUND(DATA!DF162/2,0)) -> 0 | W7: =IF(V7=0,"",V7) | X7: =SUM(D7,E7,G7,I7,K7,M7,O7,Q7,S7,U7,W7) -> 93860 | Y7: =IF(DATA!CR$273=2,IF(X7=0,0,DATA!CP283)+AP7,"") -> 7000 | Z7: =IF(Y7=0,"",Y7) -> 7000 | AA7: =IF(DATA!CR$273=2,IF(X7=0,0,DATA!CQ283),"") -> 2000 | AB7: =IF(AA7=0,"",AA7) -> 2000 | AC7: =IF(DATA!CJ$175=1,IF(X7=0,0,DATA!CR283),"") -> 200 | AD7: =IF(DATA!CR$273=2,IF(X7=0,0,DATA!CS283),"") -> 120 | AE7: =IF(AD7=0,"",AD7) -> 120 | AF7: =IF(DATA!CR273=2,IF(X7=0,0,DATA!CT283),"") -> 50 | AG7: 300 | AH7: =IF(DATA!CR$273=2,DATA!CV283,"") | AI7: =IF(DATA!O29="","",DATA!O29) -> 8000 | AJ7: =SUM(Z7,AB7,AC7,AE7,AF7,AG7,AH7,AI7) -> 17670 | AK7: =X7-AJ7 -> 76190 | AL7: =DATA!BS267 -> 0.30392 | AO7: =IF(DATA!CL274=2,ROUND(D7/31,0),"") | AP7: =IF(DATA!CL$274=2,DATA!U$53,0) -> 0 | AW7: =IF(DATA!CL$274=2,DATA!Q$53,DATA!L$19) -> 0
B8: 2 | C8: 44287 | D8: 55410 | E8: 16840 | G8: 6649 | H8: 5732 | I8: 14961 | J8: 0 | L8: 0 | N8: 0 | R8: 0 | T8: 0 | V8: 0 | X8: 93860 | Y8: =IF(DATA!CR$273=2,IF(X8=0,0,DATA!CP284)+AP8,"") -> 7000 | Z8: =IF(Y8=0,"",Y8) -> 7000 | AA8: =IF(DATA!CR$273=2,IF(X8=0,0,DATA!CQ284),"") -> 2000 | AB8: =IF(AA8=0,"",AA8) -> 2000 | AC8: =IF(DATA!CJ$175=1,IF(X8=0,0,DATA!CR284),"") -> 200 | AD8: =IF(DATA!CR$273=2,IF(X8=0,0,DATA!CS284),"") -> 120 | AE8: =IF(AD8=0,"",AD8) -> 120 | AG8: 300 | AH8: =IF(DATA!CR$273=2,DATA!CV283,"") | AI8: =IF(DATA!O30="","",DATA!O30) -> 8000 | AJ8: =SUM(Z8,AB8,AC8,AE8,AF8,AG8,AH8,AI8) -> 17620 | AK8: =X8-AJ8 -> 76240 | AL8: =DATA!BS268 -> 0.30392 | AM8: =IF(AK8="",0,1) -> 1 | AP8: =IF(DATA!CL$274=2,DATA!U$53,0) -> 0 | AW8: =IF(DATA!CL$274=2,DATA!Q$53,DATA!L$19) -> 0
B9: 3 | C9: 44317 | D9: 55410 | E9: 16840 | G9: 6649 | H9: 5732 | I9: 14961 | J9: 0 | L9: 0 | N9: 0 | R9: 0 | T9: 0 | V9: 0 | X9: 93860 | Y9: =DATA!CV319 -> 7000 | Z9: =IF(Y9=0,"",Y9) -> 7000 | AA9: =DATA!CW319 -> 2000 | AB9: =IF(AA9=0,"",AA9) -> 2000 | AC9: =IF(DATA!CJ$175=1,IF(X9=0,0,DATA!CR285),"") -> 200 | AD9: =DATA!CY319 -> 120 | AE9: =IF(AD9=0,"",AD9) -> 120 | AG9: 300 | AH9: =IF(DATA!DA319=0,"",DATA!DA319) | AI9: =IF(DATA!O31="","",DATA!O31) -> 8000 | AJ9: =SUM(Z9,AB9,AC9,AE9,AF9,AG9,AH9,AI9) -> 17620 | AK9: =X9-AJ9 -> 76240 | AL9: =DATA!BS269 -> 0.30392 | AM9: =IF(AK9="",0,1) -> 1 | AP9: =IF(DATA!CL$274=2,DATA!U$53,0) -> 0 | AW9: =IF(DATA!CL$274=2,DATA!Q$53,DATA!L$19) -> 0
B10: 4 | C10: 44348 | D10: 55410 | E10: 16840 | G10: 6649 | H10: 5732 | I10: 14961 | J10: 0 | L10: 0 | N10: 0 | R10: 0 | T10: 0 | V10: 0 | X10: 93860 | Y10: =IF(X10=0,0,DATA!CP286)+AP7 -> 7000 | Z10: =IF(Y10=0,"",Y10) -> 7000 | AA10: =IF(X10=0,0,DATA!CQ286) -> 2000 | AB10: =IF(AA10=0,"",AA10) -> 2000 | AC10: =IF(DATA!CJ$175=1,IF(X10=0,0,DATA!CR286),"") -> 200 | AD10: =IF(X10=0,0,DATA!CS286) -> 120 | AE10: =IF(AD10=0,"",AD10) -> 120 | AG10: 300 | AH10: =DATA!CV286 | AI10: =IF(DATA!O32="","",DATA!O32) -> 8000 | AJ10: =SUM(Z10,AB10,AC10,AE10,AF10,AG10,AH10,AI10) -> 17620 | AK10: =X10-AJ10 -> 76240 | AL10: =DATA!BS270 -> 0.30392 | AM10: =IF(AK10="",0,1) -> 1 | AP10: =ROUND(DATA!AQ182*10/100,0) -> 0 | AW10: =IF(DATA!CL$274=2,DATA!Q$53,DATA!L$19) -> 0
B11: 5 | C11: 44378 | D11: 55410 | E11: 16840 | G11: 6649 | H11: 5732 | I11: 14961 | J11: 0 | L11: 0 | N11: 0 | R11: 0 | T11: 0 | V11: 0 | X11: 93860 | Y11: =IF(X11=0,0,DATA!CP287)+AP7 -> 7000 | Z11: =IF(Y11=0,"",Y11) -> 7000 | AA11: =IF(X11=0,0,DATA!CQ287) -> 2000 | AB11: =IF(AA11=0,"",AA11) -> 2000 | AC11: =IF(DATA!CJ$175=1,IF(X11=0,0,DATA!CR287),"") -> 200 | AD11: =IF(X11=0,0,DATA!CS287) -> 120 | AE11: =IF(AD11=0,"",AD11) -> 120 | AG11: 300 | AH11: =DATA!CV287 | AI11: =IF(DATA!Q29="","",DATA!Q29) -> 8000 | AJ11: =SUM(Z11,AB11,AC11,AE11,AF11,AG11,AH11,AI11) -> 17620 | AK11: =X11-AJ11 -> 76240 | AL11: =DATA!BS271 -> 0.33536 | AM11: =IF(AK11="",0,1) -> 1 | AO11: =IF(DATA!CF$182=2,AP10,AP12) -> 0 | AP11: =ROUND(DATA!AQ182*90/100,0) -> 0 | AW11: =IF(DATA!CL$274=2,DATA!Q$53,DATA!L$19) -> 0
B12: 6 | C12: 44409 | D12: 55410 | E12: 18582 | G12: 6649 | H12: =IF(DATA!CL$274=2,DATA!L$24,DATA!CL288) -> 5891 | I12: 14961 | J12: =DATA!L$13 -> 0 | K12: =IF(J12=0,"",J12) | L12: =DATA!CH288 -> 0 | M12: =IF(L12=0,"",L12) | N12: =DATA!CZ288 -> 0 | O12: =IF(N12=0,"",N12) | R12: =DATA!CJ288 -> 0 | S12: =IF(R12=0,"",R12) | T12: =IF(DATA!DK183=0,"",DATA!DK183) | U12: =T12 | V12: =DATA!DF167 -> 0 | W12: =IF(V12=0,"",V12) | X12: =SUM(D12,E12,G12,I12,K12,M12,O12,Q12,S12,U12,W12) -> 95602 | Y12: =IF(X12=0,0,DATA!CP288)+AP7 -> 7000 | Z12: =IF(Y12=0,"",Y12) -> 7000 | AA12: =IF(X12=0,0,DATA!CQ288) -> 2000 | AB12: =IF(AA12=0,"",AA12) -> 2000 | AC12: =IF(DATA!CJ$175=1,IF(X12=0,0,DATA!CR288),"") -> 200 | AD12: =IF(X12=0,0,DATA!CS288) -> 120 | AE12: =IF(AD12=0,"",AD12) -> 120 | AF12: =IF(DATA!CN196=1,Bill!#REF!,"") | AG12: 300 | AH12: =DATA!CV288 | AI12: =IF(DATA!Q30="","",DATA!Q30) -> 8000 | AJ12: =SUM(Z12,AB12,AC12,AE12,AF12,AG12,AH12,AI12) -> 17620 | AK12: =X12-AJ12 -> 77982 | AL12: =DATA!BS272 -> 0.33536 | AM12: =IF(AK12="",0,1) -> 1 | AP12: =SUM(AP10:AP11) -> 0 | AW12: =IF(DATA!CL$274=2,DATA!Q$53,DATA!L$19) -> 0
B13: 7 | C13: 44440 | D13: 55410 | E13: 18582 | G13: 6649 | H13: 5891 | I13: 14961 | J13: 0 | L13: 0 | N13: 0 | R13: 0 | V13: 0 | X13: 95602 | Y13: =IF(X13=0,0,DATA!CP289)+AP7 -> 7000 | Z13: =IF(Y13=0,"",Y13) -> 7000 | AA13: =IF(X13=0,0,DATA!CQ289) -> 2000 | AB13: =IF(AA13=0,"",AA13) -> 2000 | AC13: =IF(DATA!CJ$175=1,IF(X13=0,0,DATA!CR289),"") -> 200 | AD13: =IF(X13=0,0,DATA!CS289) -> 120 | AE13: =IF(AD13=0,"",AD13) -> 120 | AG13: 300 | AH13: =DATA!CV289 | AI13: =IF(DATA!Q31="","",DATA!Q31) -> 8000 | AJ13: =SUM(Z13,AB13,AC13,AE13,AF13,AG13,AH13,AI13) -> 17620 | AK13: =X13-AJ13 -> 77982 | AL13: =DATA!BS273 -> 0.33536 | AM13: =IF(AK13="",0,1) -> 1 | AW13: =IF(DATA!CL$274=2,DATA!Q$53,DATA!L$19) -> 0
B14: 8 | C14: 44470 | D14: 56870 | E14: 19072 | G14: 6824 | H14: 5891 | I14: 15355 | J14: 0 | L14: 0 | N14: 0 | R14: 0 | V14: 0 | X14: 98121 | Y14: =IF(X14=0,0,DATA!CP290)+AP7 -> 7000 | Z14: =IF(Y14=0,"",Y14) -> 7000 | AA14: =IF(X14=0,0,DATA!CQ290) -> 2000 | AB14: =IF(AA14=0,"",AA14) -> 2000 | AC14: =IF(DATA!CJ$175=1,IF(X14=0,0,DATA!CR290),"") -> 200 | AD14: =IF(X14=0,0,DATA!CS290) -> 120 | AE14: =IF(AD14=0,"",AD14) -> 120 | AG14: 300 | AH14: =DATA!CV290 | AI14: =IF(DATA!Q32="","",DATA!Q32) -> 8000 | AJ14: =SUM(Z14,AB14,AC14,AE14,AF14,AG14,AH14,AI14) -> 17620 | AK14: =X14-AJ14 -> 80501 | AL14: =DATA!BS274 -> 0.33536 | AM14: =IF(AK14="",0,1) -> 1 | AP14: AP | AQ14: TS | AW14: =IF(DATA!CL$274=2,DATA!Q$53,DATA!L$19) -> 0
B15: 9 | C15: 44501 | D15: 56870 | E15: 19072 | G15: 6824 | H15: 5891 | I15: 15355 | J15: 0 | L15: 0 | N15: 0 | R15: 0 | V15: 0 | X15: 98121 | Y15: =IF(X15=0,0,DATA!CP291)+AP7 -> 7000 | Z15: =IF(Y15=0,"",Y15) -> 7000 | AA15: =IF(X15=0,0,DATA!CQ291) -> 2000 | AB15: =IF(AA15=0,"",AA15) -> 2000 | AC15: =IF(DATA!CJ$175=1,IF(X15=0,0,DATA!CR291),"") -> 200 | AD15: =IF(X15=0,0,DATA!CS291) -> 120 | AE15: =IF(AD15=0,"",AD15) -> 120 | AG15: 300 | AH15: =DATA!CV291 | AI15: =IF(DATA!T29="","",DATA!T29) -> 8000 | AJ15: =SUM(Z15,AB15,AC15,AE15,AF15,AG15,AH15,AI15) -> 17620 | AK15: =X15-AJ15 -> 80501 | AL15: =DATA!BR275 -> 0.30392 | AM15: =IF(AK15="",0,1) -> 1 | AO15: =IF(DATA!CF$182=2,AQ15,0) -> 0 | AP15: =ROUND(DATA!AQ181*10/100,0) -> 0 | AQ15: =ROUND(DATA!AT183*10/100,0) -> 3 | AW15: =IF(DATA!CL$274=2,DATA!Q$53,DATA!L$19) -> 0
B16: 10 | C16: 44531 | D16: 56870 | E16: 19072 | G16: 6824 | H16: 5891 | I16: 15355 | J16: 0 | L16: 0 | N16: 0 | R16: 0 | V16: 0 | X16: 98121 | Y16: =IF(X16=0,0,DATA!CP292) -> 7000 | Z16: =IF(Y16=0,"",Y16) -> 7000 | AA16: =IF(X16=0,0,DATA!CQ292) -> 2000 | AB16: =IF(AA16=0,"",AA16) -> 2000 | AC16: =IF(DATA!CJ$175=1,IF(X16=0,0,DATA!CR292),"") -> 200 | AD16: =IF(X16=0,0,DATA!CS292) -> 120 | AE16: =IF(AD16=0,"",AD16) -> 120 | AF16: 100 | AG16: 300 | AI16: =IF(DATA!T30="","",DATA!T30) -> 20000 | AJ16: =SUM(Z16,AB16,AC16,AE16,AF16,AG16,AH16,AI16) -> 29720 | AK16: =X16-AJ16 -> 68401 | AL16: =DATA!BR276 -> 0.30392 | AM16: =IF(AK16="",0,1) -> 1 | AO16: =IF(DATA!CF$182=2,AP15,AP17) -> 0 | AP16: =ROUND(DATA!AQ181*90/100,0) -> 0 | AQ16: =ROUND(DATA!AT183*90/100,0) -> 28 | AW16: =IF(DATA!CL$274=2,"",DATA!L$19) -> 0
B17: 11 | C17: 44562 | D17: 56870 | E17: 22052 | G17: 6824 | H17: 5891 | I17: 15355 | J17: 0 | L17: 0 | N17: 0 | R17: 0 | V17: 0 | X17: 101101 | Y17: =IF(X17=0,0,DATA!CP293) -> 7000 | Z17: =IF(Y17=0,"",Y17) -> 7000 | AA17: =IF(X17=0,0,DATA!CQ293) -> 2000 | AB17: =IF(AA17=0,"",AA17) -> 2000 | AC17: =IF(DATA!CJ$175=1,IF(X17=0,0,DATA!CR293),"") -> 200 | AD17: =IF(X17=0,0,DATA!CS293) -> 120 | AE17: =IF(AD17=0,"",AD17) -> 120 | AG17: 300 | AH17: =DATA!CV293 | AI17: =IF(DATA!T31="","",DATA!T31) | AJ17: =SUM(Z17,AB17,AC17,AE17,AF17,AG17,AH17,AI17) -> 9620 | AK17: =X17-AJ17 -> 91481 | AL17: =DATA!BR277 -> 0.33536 | AM17: =IF(AK17="",0,1) -> 1 | AO17: =IF(DATA!CF$182=2,AQ15,AQ17) -> 31 | AP17: =SUM(AP15:AP16) -> 0 | AQ17: =SUM(AQ15:AQ16) -> 31 | AW17: =IF(DATA!CL$274=2,"",DATA!L$19) -> 0
B18: 12 | C18: 44593 | D18: 56870 | E18: 22052 | G18: 6824 | H18: 5891 | I18: 15355 | J18: 0 | L18: 0 | N18: 0 | R18: 0 | V18: 0 | X18: 101101 | Y18: =IF(X18=0,0,DATA!CP294) -> 7000 | Z18: =IF(Y18=0,"",Y18) -> 7000 | AA18: =IF(X18=0,0,DATA!CQ294) -> 2000 | AB18: =IF(AA18=0,"",AA18) -> 2000 | AC18: =IF(DATA!CJ$175=1,IF(X18=0,0,DATA!CR294),"") -> 200 | AD18: =IF(X18=0,0,DATA!CS294) -> 120 | AE18: =IF(AD18=0,"",AD18) -> 120 | AG18: 300 | AH18: =DATA!CV294 | AI18: =IF(DATA!T32="","",DATA!T32) | AJ18: =SUM(Z18,AB18,AC18,AE18,AF18,AG18,AH18,AI18) -> 9620 | AK18: =X18-AJ18 -> 91481 | AL18: =DATA!BR278 -> 0.33536 | AM18: =IF(AK18="",0,1) -> 1 | AT18: =IF(DATA!CL$274=2,DATA!#REF!,0) -> 0 | AW18: =IF(DATA!CL$274=2,"",DATA!L$19) -> 0
B19: 13 | C19: SEL for 15 days | D19: 27705 | E19: 8420 | G19: 3325 | X19: 39450 | Y19: =IF(DATA!CL$274=1,AO16,AO17) -> 0 | Z19: =Y19 -> 0 | AJ19: =Z19 -> 0 | AK19: =X19-AJ19 -> 39450 | AM19: =IF(AK19="",0,1) -> 1
C20: pay fixation Arrears | Y20: =IF(DATA!CL$274=1,AO11,0) -> 0 | AL20: =IF(DATA!CL274=1,AP12,0) -> 0 | AM20: =IF(AK20="",0,1) -> 0
B21: 15 | C21: July DA - 1 M | D21: =AT21 | E21: 1742 | G21: =AV21 | L21: =AX21 | R21: =AW21 -> 0 | T21: =AY21 | X21: 1742 | AK21: =IF(X21="","",(X21-AJ21)) -> 1742 | AM21: =IF(AK21="",0,1) -> 1 | AS21: =IF(C21="","",DATA!BH280+DATA!BI282+DATA!BJ282+DATA!BL285+DATA!BO295+DATA!BL293) -> #VALUE! | AT21: =IF(DATA!BK289=1,DATA!BH280,"") | AU21: =IF(DATA!BK289=1,DATA!BI282,"") | AV21: =IF(DATA!BK289=1,DATA!BJ282,"") | AX21: =IF(DATA!BK289=1,DATA!BO295,"") | AY21: =IF(DATA!BK289=1,DATA!BL293,"")
B22: 18 | C22: DA - 1 (1,2,3) | D22: =DATA!CE304 | E22: 52244 | G22: =IF(DATA!CG304=0,"",DATA!CG304) | H22: =AZ22 | I22: =IF(DATA!CK304=0,"",DATA!CK304) | L22: =IF(C22="","",DATA!CH304) -> 0 | R22: =DATA!CJ304 | T22: =IF(C22="","",DATA!CI304) -> 0 | X22: 52244 | Y22: =DATA!CO304 | Z22: 52244 | AJ22: =IF(D22="","",SUM(Z22,AB22,AC22,AE22,AF22,AG22,AH22,AI22)) | AK22: 0 | AM22: =IF(AK22="",0,1) -> 1 | AZ22: =IF(DATA!CL$274=1,DATA!CK304,"")
B23: 19 | C23: DA - 2 (1,2,3) | D23: =DATA!CE305 | E23: 53473 | G23: =IF(DATA!CG305=0,"",DATA!CG305) | H23: =AZ23 | L23: =IF(C23="","",DATA!CH305) -> 0 | R23: =DATA!CJ305 | T23: =IF(C23="","",DATA!CI305) -> 0 | X23: 53473 | Y23: =DATA!CO305 | Z23: 53473 | AJ23: =IF(D23="","",SUM(Z23,AB23,AC23,AE23,AF23,AG23,AH23,AI23)) | AK23: 0 | AM23: =IF(AK23="",0,1) -> 1 | AZ23: =IF(DATA!CL$274=1,DATA!CK305,"")
B24: 21 | C24: =IF(DATA!L15="","","Child Fee Conces") | X24: =IF(DATA!L15="","",DATA!L15) | AK24: =IF(X24="","",X24-AJ24) | AM24: =IF(AK24="",0,1) -> 0
C25: Grand Totals | D25: =SUM(D7:D24) -> 699925 | E25: =SUM(E7:E24) -> 338563 | G25: =SUM(G7:G24) -> 83988 | H25: =SUM(H7:H24) -> 69897 | I25: =SUM(I7:I24) -> 181502 | J25: =SUM(J7:J24) -> 0 | K25: =SUM(K7:K24) -> 0 | L25: =SUM(L7:L24) -> 0 | M25: =SUM(M7:M24) -> 0 | N25: =SUM(N7:N24) -> 0 | ... AJ25: =SUM(AJ7:AJ24) -> 207590 | AK25: =X25-AJ25 -> 1096388
D29: Signature of the DDO | AF29: Signature of the Employee
B32: Prepared by: C.Ramanjaneyulu, S.A (P.S), www.teacherNews.in

Sheet Annexure -I I
B2: =IF(DATA!$AH$49=2,"Old Tax IT Calculation","New Tax IT Calculation") -> Old Tax IT Calculation
B4: Financial Year 2021-22 | G4: ANNEXURE - II | K4: Assessment year 2022-23
B5: =IF(DATA!$AH$49=1,"INCOME TAX CALCULATION 2021-22 (New Regime)","INCOME TAX CALCULATION 2021-22 (Old Regime)") -> INCOME TAX CALCULATION 2021-22 (Old Regime)
B6: Name | D6: =CONCATENATE(DATA!BN172," ",DATA!E10) -> Sri. A.Nagesh | H6: Office/ School: | I6: =CONCATENATE(DATA!E21," , ",DATA!E22," (","Mandal",")"," ") -> Velgode , Velgode (Mandal)
B7: Designation | D7: =DATA!CD169 -> Deputy Executive Engineer | H7: Address: | I7: =CONCATENATE(DATA!E13,",",DATA!E14,",",DATA!E15," ( Mandal )") -> Executive Engineer,TGP Division No.1,Velgode,Velgode ( Mandal )
C8: Whether living in | F8: =DATA!CF177 -> Rented House | H8: =CONCATENATE("PAN No : ",DATA!E12) -> PAN No : | J8: Treasury Id. No. | L8: =IF(DATA!E18="","",DATA!E18)
B9: 1 | C9: Gross Salary……… | J9: Rs. | L9: =Bill!X25 -> 1303978
B10: 2 | C10: H.R.A. Exemption as per eligibility U/s 10(13-A) | Y10: =Bill!D25+Bill!E25 -> 1038488
C11: a) | D11: Actual HRA received | J11: Rs. | K11: =IF(DATA!AH49=1,"",Bill!G25+Bill!N25) -> 83988
C12: b) | D12: Actual House Rent paid by you minus 10% of your Salary | I12: =IF(DATA!AH49=1,"",IF(DATA!CE178=2,"",CONCATENATE("Rent @ ",DATA!S11))) -> Rent @ 12000 | J12: Rs. | K12: =IF(DATA!AH49=1,"",IF(AC25=1,"",DATA!CF176)) -> 40150 | M12: House rent paid monthly | P12: =DATA!S11 -> 12000 | Q12: X 12 | U12: =ROUND(DATA!S11*12,0) -> 144000
C13: c) | D13: 40% of Salary (Salary means Basic Pay+D.A) | J13: Rs. | K13: =IF(DATA!AH49=1,"",IF(AC25=1,"",DATA!CF244)) -> 415396 | L13: =MIN(K11:K13) -> 40150 | P13: 10% of salary | U13: =ROUND(Y10*10%,-1) -> 103850 | W13: =CONCATENATE(" ( Pay - ",Bill!D25," + DA - ",Z13," )") -> ( Pay - 699925 + DA - 338563 ) | Z13: =IF(DATA!CH262=1,0,Bill!E25) -> 338563
J14: Rs. | L14: =K14 -> 0
B15: 3 | C15: Total Salary (1-2) | J15: Rs. | L15: =L9-L13 -> 1263828 | Q15: -- | U15: =ROUND(U12-U13,0) -> 40150 | Y15: =U13+Bill!G25 -> 187838
B16: 4 | C16: Deductions from Salary Income | Y16: =ROUND(Y15/12,-2)+100 -> 15800
C17: a) | D17: Exemption from Conveyance Allowance U/s. 10(14) (i) | J17: Rs. | K17: =IF(DATA!AH49=1,"",DATA!CI245) -> 0
C18: b) | D18: Profession Tax U/s 16 (3) B | J18: Rs. | K18: =IF(DATA!AH49=1,"",IF(AC25=1,"",Bill!AC25)) -> 2400 | L18: =IF(DATA!AH49=1,0,IF(DATA!CJ175=1,(DATA!CG243+DATA!CJ245),MAX(K17:K18))) -> 2400
B19: 5 | C19: Income From Salary (3-4) | J19: Rs. | L19: =L15-L18 -> 1261428
B20: 6 | C20: Less: Standard deduction- u/s16 (Ia) | I20: =IF(DATA!BQ238=1,DATA!N38,"") | J20: =IF(DATA!BQ238=1,DATA!Q38,"") | L20: =IF(DATA!AH49=1,0,50000) -> 50000
B21: 7 | C21: Net Income from Salary (5-6) | I21: =IF(DATA!BQ238=1,DATA!N39,"") | J21: =IF(DATA!BQ238=1,DATA!Q39,"") | L21: =L19-L20 -> 1211428
B22: 8 | C22: =DATA!BB209 -> Income From other sources | I22: =IF(DATA!BQ238=1,DATA!N40,"") | J22: =IF(DATA!BQ238=1,DATA!Q40,"") | L22: =DATA!G38 -> 0 | AC22: New Tax Slab
C23: =DATA!BB210 -> Income From Capital Gains | I23: =IF(DATA!BQ238=1,"Interest Paid on Housing Loan","") | J23: =IF(DATA!BQ238=1,DATA!BQ229,"") | L23: =DATA!G39 -> 0 | AC23: Old Tax Slab
B24: 9 | C24: =DATA!BN239 -> Income | E24: from House Property U/s 24 (vi) | I24: =IF(DATA!BQ238=1,DATA!N41,"") | J24: =IF(DATA!BQ238=1,DATA!Q41,"") | L24: =IF(M24="",0,M24) -> 0 | M24: =CONCATENATE("",DATA!BM239) | AA24: =IF(AA25>AA31,AA31,AA25) -> 0
B25: 10 | C25: Gross Total Income (7+8+9) | L25: =SUM(L21:L23)+L24 -> 1211428 | Z25: =IF(X27>X28,Z27,Z26) -> 84000 | AA25: =IF(Z31>Z25,(Z31-Z25),IF(Z31<Z25,-(Z31-Z25),0)) -> 0 | AC25: =DATA!AH49 -> 2
B26: 11 | C26: Deductions | Z26: =IF(Y27<X28,Z31,Z27) -> 84000
C27: a) | D27: 80G | E27: E.W.F. & S.W.F & CMRF | J27: Rs. | K27: =IF(DATA!AH49=1,"",Bill!AF25) -> 150 | X27: =Bill!Y25+Bill!AA25+Bill!AD25+Bill!AH25+K41+K42+K43+K44+K45 -> 109440 | Y27: =Bill!AA25+Bill!AD25+Bill!AH25+K41+K42+K43+K44+K45 -> 25440 | Z27: =IF(Y27>X28,0,IF(Y27<X28,-(Y27-X28))) -> 124560
C28: b) | D28: =DATA!BL211 -> 80EE | E28: =DATA!BO190 -> Interest of Housing Loan 80EE | J28: Rs. | K28: =IF(DATA!AH49=1,"",DATA!BP193) -> 0 | X28: 150000
C29: c) | D29: =DATA!BL212 -> 80EEA | E29: =DATA!BO191 -> Interest of HBA Loan 80EEA | J29: Rs. | K29: =IF(DATA!AH49=1,"",DATA!BP194) -> 0 | X29: =IF((X27-X28)>0,(X27-X28),IF((X27-X28)<0,0)) -> 0
C30: d) | D30: =DATA!BL170 -> 24B | E30: =DATA!BO189 -> Interest of Housing Loan Section 24 | J30: Rs. | K30: =IF(DATA!AH49=1,"",DATA!BQ192) -> 0
C31: e) | D31: 80U | E31: =DATA!BL223 -> Disabled Person (PH)-above 40% disability ( Rule 11A) | J31: Rs. | K31: =IF(DATA!AH49=1,"",DATA!BL225) -> 0 | Z31: =Bill!Y25 -> 84000 | AA31: 50000
C32: f) | D32: 80d | E32: Employees Health Cards Premium in AP | J32: Rs. | K32: =IF(DATA!AH49=1,"",IF(AC25=1,"",Bill!AG25)) -> 3600 | Z32: =IF(DATA!CF174=1,Bill!Y25,Z25) -> 84000
C34: TOTAL----------- | J34: Rs. | K34: =SUM(K27:K33) -> 3750 | L34: =K34 -> 3750
B35: 12 | C35: Gross Total Income (10-11) | J35: Rs. | L35: =IF((L25-L34)>0,(L25-L34),IF((L25-L34)<0,0)) -> 1207678
B36: 13 | C36: Savings U/s 80C ( Limited to Rs.1,50,000 )
C37: a) | D37: =IF(DATA!CF182=1,DATA!CD182,"CPS Employees Contribution Amount U/s 80CCD 1") -> PF | I37: =CONCATENATE("No. : ",DATA!O23) -> No. : | J37: Rs. | K37: =IF(DATA!AH49=1,"",Bill!Z25) -> 189717
C38: b) | D38: APGLI | F38: A/C No: | G38: =DATA!S23 -> 0 | J38: Rs. | K38: =IF(DATA!AH49=1,"",Bill!AB25) -> 24000
C39: c) | D39: GIS | J39: Rs. | K39: =IF(DATA!AH49=1,"",Bill!AE25) -> 1440
C40: d) | D40: LIC Policies Monthly Premium in Salary | J40: Rs. | K40: =IF(DATA!AH49=1,"",Bill!AH25) -> 0
C41: e) | D41: =DATA!BI189 -> LIC Policies premium - Yearly | J41: Rs. | K41: =IF(DATA!AH49=1,"",DATA!G27) -> 0
C42: f) | D42: =DATA!BI190 -> Exide Life Insurance | J42: Rs. | K42: =IF(DATA!AH49=1,"",DATA!G28) -> 0
C43: g) | D43: =DATA!BG189 -> Sukanya Samruddhi Yojana | J43: Rs. | K43: =IF(DATA!AH49=1,"",DATA!G29) -> 0
...

Sheet Form-16
B2: =IF(DATA!AH49=1,"FORM No. 16 - New Regime","FORM No. 16 - Old Regime") -> FORM No. 16 - Old Regime
B3: ( Vide rule 31(1)(a) of Income Tax Rules, 1962 )
B4: for Tax deducted at source from income chargeable under the head "salaries"
B5: NAME AND ADDRESS OF THE EMPLOYER | G5: NAME AND DESIGNATION OF THE EMPLOYEE
B6: =CONCATENATE("Sri./Smt. "," ",DATA!E19) -> Sri./Smt. N.C.Subbarayudu | G6: =CONCATENATE(DATA!BN172," ",DATA!E10) -> Sri. A.Nagesh
B7: =DATA!E20 -> Executive Engineer,TGP Division No.1 | G7: =DATA!CD169 -> Deputy Executive Engineer
B8: =DATA!E21 -> Velgode | G8: =CONCATENATE(DATA!E13,", ",DATA!E14) -> Executive Engineer,TGP Division No.1, Velgode
B9: =CONCATENATE(DATA!E22," ("," Mandal",")") -> Velgode ( Mandal) | G9: =CONCATENATE(DATA!E15," (","Mandal",")") -> Velgode (Mandal)
B10: PAN No. of Deductor | E10: TAN No. of Deductor | G10: PAN OF Employee | K10: Treasury Id. No.
B11: =IF(DATA!D23="","",DATA!D23) | E11: =IF(DATA!F23="","",DATA!F23) | G11: =IF(DATA!E12="","",DATA!E12) | K11: =IF(DATA!E18="","",DATA!E18)
B12: Acknowledgement Nos.of allquarterly statements of TDS under sub-section 200 as provided by TIN facilitation center or NSDL web-site
B13: Quarter | E13: Acknowledgement No | F13: Amount | G13: Period | K13: Assessment
B14: 1 (Mar to May) | F14: =IF('Annexure -I I'!X65="","",'Annexure -I I'!X65) -> 24000 | G14: From | I14: To | K14: Year
B15: 2 (Jun to Aug) | F15: =IF('Annexure -I I'!X66="","",'Annexure -I I'!X66) -> 24000 | G15: 44256 | I15: 44620 | K15: 2022 -2023
B16: 3 (Sep to Nov) | F16: =IF('Annexure -I I'!X67="","",'Annexure -I I'!X67) -> 24000
B17: 4 (Dec to Feb) | F17: =IF('Annexure -I I'!X68="","",'Annexure -I I'!X68) -> 20000
B18: DETAILS OF SALARY PAID AND ANY OTHER INCOME AND TAX DEDUCTED
B19: 1 | C19: Gross Salary
C20: a) | D20: Salary as per provisions cotained in section 17 (1) | G20: Rs. | H20: =Bill!X25 -> 1303978
C21: b) | D21: Value of percuisites under section 17(2) | G21: Rs. | H21: 0
D22: (As Per Form No. 12BA, Wherever applicable)
C23: c) | D23: Profits in lieu of salary under section 17(3) | G23: Rs. | H23: 0
D24: (as per Form No. 12BA, Wherver applicable)
C25: d) | D25: Total | G25: Rs. | H25: =H19+H20+H21+H23 -> 1303978 | K25: Rs. | L25: =H25 -> 1303978
B26: 2 | C26: Reported Total amount of salary received | K26: Rs. | L26: =L25 -> 1303978
B27: 3 | C27: Less: Allowance to the extent exempted U/s 10
C28: a) | D28: Travel concession or assistance under section 10(5) | G28: Rs.
C29: b) | D29: Death-cum-retirement gratuity under section 10(10) | G29: Rs.
C30: c) | D30: Commuted value of pension under section 10(10A) | G30: Rs.
C31: d) | D31: Cash equivalent of leave salary encashment u/s 10(10AA) | G31: Rs.
C32: e) | D32: PH Allowence | G32: Rs. | H32: =IF('Annexure -I I'!K17="",0,'Annexure -I I'!K17) -> 0
C33: f) | D33: House rent allowance under section 10(13A) | G33: Rs. | H33: =IF(DATA!AH49=1,0,'Annexure -I I'!L13) -> 40150
C34: Total amount of exemption claimed u/s 3 (a+f) | K34: Rs. | L34: =SUM(H28:H33) -> 40150
B35: 4 | C35: Income under the Head Salaries (2-3) | K35: Rs. | L35: =L26-L34 -> 1263828
B36: 5 | C36: Less: Standard deduction- u/s 16
C37: Standard deduction under section 16(ia) | H37: =IF(DATA!AH49=1,0,50000) -> 50000
C38: Entertainment allowance under section 16(ii) | H38: 0
C39: Tax on employment under section 16(iii) | H39: =IF(DATA!AH49=1,0,(IF('Annexure -I I'!K18="",0,'Annexure -I I'!K18))) -> 2400 | K39: Rs. | L39: =SUM(H37:H39) -> 52400
B40: 6 | C40: Net Income from Salary | H40: ='Annexure -I I'!I20 | I40: ='Annexure -I I'!J20 | L40: =L35-L39 -> 1211428
B41: 7 | C41: Any other income reported by the employee under as per section 192 (2B) | H41: ='Annexure -I I'!I21 | I41: ='Annexure -I I'!J21
...

Sheet Form-16 Back
C2: b) | D2: =IF(DATA!CF182=1,"NPS U/s 80CCD (1)","NPS U/s 80CCD 2(B)") -> NPS U/s 80CCD (1)
D3: ='Annexure -I I'!D47 -> National Pension Scheme U/s 80CCD (1B) | I3: Rs. | J3: =IF(DATA!AH49=1,0,IF(DATA!AH49=1,0,'Annexure -I I'!K47)) -> 0 | K3: =IF(DATA!AH49=1,0,IF(DATA!AH49=1,0,'Annexure -I I'!L47)) -> 0
F4: Total Amount of Section a and b | L4: Rs. | M4: =IF(DATA!AH49=1,0,'Annexure -I I'!N50) -> 150000
B6: B) | C6: Other Section Under Chapter VI A | J6: Gross | K6: Qualifying
C7: ( Under Section 80E, 80G, 80TTA, 80G, 80DD etc. ) | J7: Amount | K7: Amount
C8: 80G | E8: EWF , SWF & CMRF | I8: Rs. | J8: =IF(DATA!AH49=1,0,Bill!AF25) -> 150 | K8: =J8 -> 150
C9: ='Annexure -I I'!D30 -> 24B | E9: =DATA!BO189 -> Interest of Housing Loan Section 24 | I9: Rs. | J9: =IF(DATA!AH49=1,0,IF(DATA!AH49=1,0,DATA!G33)) -> 0 | K9: =IF(DATA!AH49=1,0,IF(DATA!AH49=1,0,DATA!BP192)) -> 0
C10: =DATA!BL211 -> 80EE | E10: =DATA!BO190 -> Interest of Housing Loan 80EE | I10: Rs. | J10: =IF(DATA!AH49=1,0,IF(DATA!AH49=1,0,DATA!G34)) -> 0 | K10: =IF(DATA!AH49=1,0,IF(DATA!AH49=1,0,'Annexure -I I'!K28)) -> 0
C11: =DATA!BL212 -> 80EEA | E11: =DATA!BO191 -> Interest of HBA Loan 80EEA | I11: Rs. | J11: =IF(DATA!AH49=1,0,IF(DATA!AH49=1,0,DATA!G35)) -> 0 | K11: =IF(DATA!AH49=1,0,'Annexure -I I'!K29) -> 0
C12: ='Annexure -I I'!D31 -> 80U | E12: ='Annexure -I I'!E31 -> Disabled Person (PH)-above 40% disability ( Rule 11A) | I12: Rs. | J12: =IF(DATA!AH49=1,0,DATA!G36) -> 0 | K12: =IF(DATA!AH49=1,0,IF(DATA!AH49=1,0,DATA!BL225)) -> 0
C13: 80D | E13: Employees Health Cards Premium in AP | I13: Rs. | J13: =IF(DATA!AH49=1,0,IF(DATA!AH49=1,0,Bill!AG25)) -> 3600 | K13: =IF(DATA!AH49=1,0,IF(DATA!AH49=1,0,Bill!AG25)) -> 3600
C14: Employees Contribution towards NPS U/s 80CCD (2) | I14: Rs. | J14: =IF(DATA!AH49=1,0,'Annexure -I I'!K33) -> 0 | K14: =IF(DATA!AH49=1,0,J14) -> 0
G15: Total Under Sections 80G,80E,80DD etc….. | L15: Rs. | M15: =SUM(K8:K14) -> 3750
B16: 10 | C16: Aggregate of Deductible Amounts U/Chapter VIA (A+B)… | L16: Rs. | M16: ='Annexure -I I'!N50+'Form-16 Back'!M15 -> 153750
B18: 11 | C18: Net Taxable Income ( Column 8- Column 10) | L18: Rs. | M18: ='Annexure -I I'!L50 -> 1057680
C19: Tax on Income | J19: ='Annexure -I I'!J51 -> Tax Rs. 807680
C20: a) | D20: Upto-2,50,000 | L20: Rs. | M20: Nil
C21: b) | D21: ='Annexure -I I'!D53 -> 2,50,001/- to 5,00,000/- 5% | H21: ='Annexure -I I'!H53 -> ( 250000 @ 5% ) | L21: Rs. | M21: ='Annexure -I I'!L53 -> 12500
C22: c) | D22: ='Annexure -I I'!D54 -> 5,00,001/- to 10,00,000/- 20% | H22: ='Annexure -I I'!H54 -> ( 500000 @ 20% ) | L22: Rs. | M22: ='Annexure -I I'!L54 -> 100000
C23: d) | D23: ='Annexure -I I'!D55 -> 10,00,001/ Above - 30% | H23: ='Annexure -I I'!H55 -> ( 57680 @ 30% ) | L23: Rs. | M23: ='Annexure -I I'!L55 -> 17304
C24: e) | D24: ='Annexure -I I'!D56 | H24: ='Annexure -I I'!H56 | L24: Rs. | M24: ='Annexure -I I'!L56 -> 0
C25: f) | D25: ='Annexure -I I'!D57 | H25: ='Annexure -I I'!H57 | L25: Rs. | M25: ='Annexure -I I'!L57 -> 0
C26: g) | D26: ='Annexure -I I'!D58 | H26: ='Annexure -I I'!H58 | L26: Rs. | M26: ='Annexure -I I'!L58 -> 0
B27: 12 | C27: TAX ON TOTAL INCOME Rs.
B28: 13 | C28: Tax Rebate Rs. 12500/-upto Rs.5,00,000 Taxble Income( U/s 87 A) | L28: Rs. | M28: ='Annexure -I I'!L59 -> 0
B29: 14 | C29: TAX PAYBLE (12-13) | L29: Rs. | M29: ='Annexure -I I'!L60 -> 129804
B30: 15 | C30: Health Cess @ 1% + Education Cess @ 3% | L30: Rs. | M30: ='Annexure -I I'!L61 -> 5192
B32: 16 | C32: TAX PAYABLE (14+15) | L32: Rs. | M32: ='Annexure -I I'!L63 -> 134996
B33: 17 | C33: Less: (a) Tax deducted at source U/s 192(1) | L33: Rs.
C34: (b)Tax Paid by the Employer on behalf of the Employee U/S 192 (1A) on perquisited U/S 17 (2) | L34: Rs. | M34: ='Annexure -I I'!L65 -> 92000
B35: 18 | C35: Less: Relief under section 89 (1) (attach details) | L35: Rs. | M35: ='Annexure -I I'!L64 -> 0
B36: 20 | C36: Less: (a) Tax deducted at source U/S 192 (1) | L36: Rs.
B37: 21 | C37: (b) Tax paid by the Employer on behalf of the Employee U/S 192 (A1) on perquisited U/S 17 (2) | L37: Rs.
B39: 19 | C39: ='Annexure -I I'!J67 -> Net Tax to be Paid | L39: Rs. | M39: ='Annexure -I I'!L67 -> 42996
B41: DETAILS OF TAX DEDUCTED AND DEPOSITED INTO CENTRAL GOVERNMENT ACCOUNT
B42: ( The employer is provide tranction - wise details of tax deducted and deposited )
B44: Sl. | C44: TDS | E44: Surcharge | F44: Education | G44: Total Tax | H44: Cheque/DD | I44: BSR Code | K44: Date on | L44: Transfer
B45: No. | C45: Rs. | E45: Rs. | F45: Cess | G45: Deposited | H45: No. (if any) | I45: of Bank | K45: Which Tax | L45: vocher/chalana
F46: Rs. | G46: Rs. | I46: Branch | K46: Deposited | L46: Identification No
B47: 1
...

Sheet Form 12BB
B3: INCOME TAX RULES,1962
B4: Form 12 BB
B6: Statement showing particulars of claims by an employee for deduction of tax under section 192
B8: 1 | C8: Name and address of the Employee | J8: : | K8: =CONCATENATE(DATA!E10,", ",DATA!E13,", ",DATA!E14) -> A.Nagesh, Executive Engineer,TGP Division No.1, Velgode
B9: 2 | C9: Permanent Account Number of the Employee | J9: : | K9: =IF(DATA!E12="","",DATA!E12)
B10: 3 | C10: Financial year | G10: 2021-22 | K10: Designation | M10: : | N10: =DATA!E11 -> Deputy Executive Engineer
B11: Details of claims and Evidence thereof
B12: S.No | C12: Nature of claim | M12: Amount(Rs) | Q12: Evidence/particulars
B13: 1 | C13: House Rent Allowence:
C14: 1) | D14: Rent paid to the landlord | I14: =IF(DATA!AH49=1,0,'Annexure -I I'!P12) -> 12000 | K14: x12 | M14: =IF(DATA!AH49=1,0,'Annexure -I I'!U12) -> 144000 | Q14: =IF(DATA!AH49=1,0,"Receipt Produced") -> Receipt Produced
C15: 2) | D15: Name of the landlord
C16: 3) | D16: Address of the landlord
C17: 4) | D17: PAN number of the landlord
B18: 2 | C18: Leave travel concession or assistance
B19: 3 | C19: Deduction of interest on borrowing
C20: 1) | D20: Interest payable/paid to the lender
C21: 2) | D21: Name of the lender
C22: 3) | D22: Address of the lender
C23: 4) | D23: PAN number of the lender
C24: a) | D24: Financial institutions (if available)
C25: b) | D25: Employer (if available)
C26: c) | D26: Others
B27: 4 | C27: Deduction under Chapter VI-A | X27: ='Annexure -I I'!K37 -> 189717
B28: A) | C28: Section 80C,80CC, 80CCC and 80CCD | X28: =IF('Annexure -I I'!K47="",0,'Annexure -I I'!K47) -> 0
C29: a) | D29: ='Form-16'!C49 -> 80C | E29: ='Form-16'!D49 -> PF | M29: =IF(DATA!AH49=1,0,(X27+X28)) -> 189717 | Q29: =IF(DATA!AH49=1,0,IF(M29>0,"Salary deduction","")) -> Salary deduction
C30: b) | D30: ='Form-16'!C50 -> 80C | E30: ='Form-16'!D50 -> A.P.G.L.I | M30: =IF(DATA!AH49=1,0,'Annexure -I I'!K38) -> 24000 | Q30: =IF(DATA!AH49=1,0,IF(M30>0,"Salary deduction","")) -> Salary deduction
C31: c) | D31: ='Form-16'!C51 -> 80C | E31: ='Form-16'!D51 -> G.I.S | M31: =IF(DATA!AH49=1,0,'Annexure -I I'!K39) -> 1440 | Q31: =IF(DATA!AH49=1,0,IF(M31>0,"Salary deduction","")) -> Salary deduction
C32: d) | D32: ='Form-16'!C52 -> 80C | E32: ='Form-16'!D52 -> LIC Policies Monthly Premium in Salary | M32: =IF(DATA!AH49=1,0,'Annexure -I I'!K40) -> 0 | Q32: =IF(DATA!AH49=1,0,IF(M32>0,"Salary deduction",""))
C33: e) | D33: ='Form-16'!C53 -> 80C | E33: ='Form-16'!D53 -> LIC Policies premium - Yearly | M33: =IF(DATA!AH49=1,0,'Annexure -I I'!K41) -> 0 | Q33: =IF(DATA!AH49=1,0,IF(M33>0,"Receipt Added",""))
C34: f) | D34: ='Form-16'!C54 -> 80C | E34: ='Form-16'!D54 -> Exide Life Insurance | M34: =IF(DATA!AH49=1,0,'Annexure -I I'!K42) -> 0 | Q34: =IF(DATA!AH49=1,0,IF(M34>0,"Receipt Added",""))
C35: g) | D35: ='Form-16'!C55 -> 80C | E35: ='Form-16'!D55 -> Sukanya Samruddhi Yojana | M35: =IF(DATA!AH49=1,0,'Annexure -I I'!K43) -> 0 | Q35: =IF(DATA!AH49=1,0,IF(M35>0,"Receipt Added",""))
C36: h) | D36: ='Form-16'!C56 -> 80C | E36: ='Form-16'!D56 -> PLI (Postal Life Insurance) | M36: =IF(DATA!AH49=1,0,'Annexure -I I'!K44) -> 0 | Q36: =IF(DATA!AH49=1,0,IF(M36>0,"Receipt Added",""))
C37: j) | D37: 80C | E37: ='Form-16'!D57 -> Housing Loan Principal Amount | M37: =IF(DATA!AH49=1,0,'Annexure -I I'!K45) -> 0 | Q37: =IF(DATA!AH49=1,0,IF(M37>0,"Receipt Added",""))
D38: Total of ( 80C,80CCC,80CCD,80CCF ) | M38: =IF(DATA!AH49=1,0,'Annexure -I I'!K46+X28) -> 215157
D39: ='Annexure -I I'!C48 -> 80TTA | E39: ='Annexure -I I'!D48 -> Intrest on Saving Account ( Not Fixed Deposit ) | M39: =IF(DATA!AH49=1,0,'Annexure -I I'!K48) -> 0 | Q39: =IF(M39>0,"Receipt Added","")
B40: B) | C40: Other Sections (80E,80G,80TTA)ChapterVI-A
C41: i) | D41: ='Annexure -I I'!D27 -> 80G | E41: ='Annexure -I I'!E27 -> E.W.F. & S.W.F & CMRF | M41: ='Annexure -I I'!K27 -> 150 | Q41: =IF(M41>0,"Salary deduction","") -> Salary deduction
C42: ii) | D42: ='Annexure -I I'!D28 -> 80EE | E42: ='Annexure -I I'!E28 -> Interest of Housing Loan 80EE | M42: =IF(DATA!AH49=1,0,'Annexure -I I'!K28) -> 0 | Q42: =IF(DATA!AH49=1,0,IF(M42>0,"Receipt Added",""))
C43: iii) | D43: ='Annexure -I I'!D29 -> 80EEA | E43: ='Annexure -I I'!E29 -> Interest of HBA Loan 80EEA | M43: =IF(DATA!AH49=1,0,'Annexure -I I'!K29) -> 0 | Q43: =IF(DATA!AH49=1,0,IF(M43>0,"Receipt Added",""))
C44: iv) | D44: ='Annexure -I I'!D30 -> 24B | E44: ='Annexure -I I'!E30 -> Interest of Housing Loan Section 24 | M44: =IF(DATA!AH49=1,0,'Annexure -I I'!K30) -> 0 | Q44: =IF(DATA!AH49=1,0,IF(M44>0,"Receipt Added",""))
...

Sheet Form 10E
AB2: Detail | AC2: 2020-21 | AD2: Detail | AE2: 2020-21
B4: FORM NO.10E | AB4: Total income (excluding salary received in arrars or advance) | AC4: ='Annexure -I I'!L50-AC6 -> 1057680 | AD4: Net Taxable Income | AE4: =AC4 -> 1057680
B5: [ See rule 21AA ]
B6: 1 | C6: Name and address of the Employee | L6: =CONCATENATE(DATA!BN172," ",DATA!E10,", ",DATA!CD169,", ",DATA!E13," , ",DATA!E14,", ",DATA!E15," (","Mandal",")"," ") -> Sri. A.Nagesh, Deputy Executive Engineer, Executive Engineer,TGP Division No.1 , Velgode, Velgode (Mandal) | AB6: Arrears Received | AC6: =IF(AN19="","",AN19) -> 0 | AD6: Arrears Received | AE6: 0
AB7: Total Taxable Income | AC7: =SUM(AC4:AC6) -> 1057680 | AD7: Total Taxable Income | AE7: =SUM(AE4:AE6) -> 1057680
B8: 2 | C8: Permanent Account Number | L8: =IF(DATA!E12="","",DATA!E12) | AB8: Up to Rs. 2,50,000 | AC8: 0 | AD8: Up to Rs. 2,50,000 | AE8: 0 | AT8: Yes
B9: 3 | C9: Residential Status | M9: Resident | AB9: Rs.2,50,001 To 5,00,000. (@ 5%) | AC9: =IF(AH9>0,AH9,0)*5% -> 12500 | AD9: Rs.2,50,001 To 5,00,000. (@ 5%) | AE9: =IF(AJ9>0,AJ9,0)*5% -> 12500 | AG9: =AC7-250000 -> 807680 | AH9: =IF(AG9>250000,250000,AG9) -> 250000 | AI9: =AE7-250000 -> 807680 | AJ9: =IF(AI9>250000,250000,AI9) -> 250000 | AT9: No
AB10: Rs.5,00,001 To 10,00,000. (@ 20%) | AC10: =IF(AH10>0,AH10,0)*20% -> 100000 | AD10: Rs.5,00,001 To 10,00,000. (@ 20%) | AE10: =IF(AJ10>0,AJ10,0)*20% -> 100000 | AG10: =AC7-500000 -> 557680 | AH10: =IF(AG10>500000,500000,AG10) -> 500000 | AI10: =AE7-500000 -> 557680 | AJ10: =IF(AI10>500000,500000,AI10) -> 500000 | AL10: Financil Year | AM10: Taxable | AN10: Arrears | AU10: REBATE AMOUNT UNDER SECTION 87A OF INCOME TAX ACT, 1961
C11: ="Particulars of income referred to in rule 21A of the Income Tax rules, 1962, during the previous year relevent to Assessment year"&" "&"2021"&""&"-"&""&"2022" -> Particulars of income referred to in rule 21A of the Income Tax rules, 1962, during the previous year relevent to Assessment year 2021-2022 | AB11: above Rs.10,00,001. (@ 30%) | AC11: =IF(AH11>0,AH11,0)*30% -> 17304 | AD11: above Rs.10,00,001. (@ 30%) | AE11: =IF(AJ11>0,AJ11,0)*30% -> 17304 | AG11: =AC7-1000000 -> 57680 | AH11: =IF(AG11>500000,500000,AG11) -> 57680 | AI11: =AE7-1000000 -> 57680 | AJ11: =IF(AI11>500000,500000,AI11) -> 57680 | AL11: 2020-21 | AM11: =DATA!K45 -> 0 | AN11: =DATA!F45 -> 0 | AT11: 2
AB12: Tax rebate U/s 87A | AC12: ='Annexure -I I'!L59 -> 0 | AD12: Tax rebate U/s 87A | AE12: =IF(AE7>500000,0,AC12) -> 0 | AL12: 2019-20 | AM12: =DATA!K46 -> 0 | AN12: =DATA!F46 -> 0 | AU12: S. No. | AV12: Financial Year | AW12: Rebate Available
B13: 1 | C13: a. | D13: Salary received in arrears or in advance in accordance with the provisions of sub-rule (2) of rule 21A | S13: Rs. | T13: =I81 -> 0 | AB13: Total | AC13: =IF((SUM(AC9:AC11)-AC12)>0,(SUM(AC9:AC11)-AC12),0) -> 129804 | AD13: Total | AE13: =IF((SUM(AE9:AE11)-AE12)>0,(SUM(AE9:AE11)-AE12),0) -> 129804 | AL13: 2016-17 | AM13: =DATA!K49 -> 0 | AN13: =DATA!F49 -> 0 | AU13: 1 | AV13: 2018-19 & Subsequent Years unless withdrawn | AW13: 2,500/-
AB14: Health Cess @ 1% | AC14: =ROUND(AC13*1%,0.1) -> 1298 | AD14: Health Cess @ 1% | AE14: =ROUND(AE13*1%,0.1) -> 1298 | AL14: =B77 -> 2017-18 | AM14: =DATA!K48 -> 0 | AN14: =DATA!F48 -> 0 | AU14: 2 | AV14: 2017-18 | AW14: 2,500/-
C15: b. | D15: Pament in the nature of gratuity in respect of past services, extending over a period of not less than 5 years in accordance with the provisions of sub-rule (3) of rule 21A | S15: Rs. | T15: Not Applicable | AB15: Education Cess @ 3% | AC15: =ROUND(AC13*3%,0.1) -> 3894 | AD15: Education Cess @ 3% | AE15: =ROUND(AE13*3%,0.1) -> 3894 | AL15: 2018-19 | AM15: =DATA!K47 -> 0 | AN15: =DATA!F47 -> 0 | AU15: 3 | AV15: 2016-17 | AW15: 5,000/-
AB16: Total Tax | AC16: =SUM(AC13:AC15) -> 134996 | AD16: Total Tax | AE16: =SUM(AE13:AE15) -> 134996 | AF16: =AC16-AE16 -> 0 | AL16: 2015-16 | AM16: =DATA!K50 -> 0 | AN16: =DATA!F50 -> 0 | AU16: 4 | AV16: 2015-16 | AW16: 2,000/-
AB17: Detail | AC17: 2017-18 | AD17: Detail | AE17: 2017-18 | AU17: 5 | AV17: 2014-15 | AW17: 2,000/-
C18: c. | D18: Payment in the nature of compensation from the employer or former employer at or in connection with termination of employment after continuous service of not less than 3 years or where the unexpired portion of term of employment is also not less than 3 years in accordancewith the provisions of sub rule (4) of the 21A | S18: Rs. | T18: Not Applicable | AF18: | | AU18: 6 | AV18: 2013-14 | AW18: 2,000/-
AB19: Net Taxable Income | AC19: =IF(AM14="","",AM14) -> 0 | AD19: Net Taxable Income | AE19: =AC19 -> 0 | AL19: Total Arrears | AN19: =SUM(AN11:AN16) -> 0 | AO19: =IF(DATA!CL274=2,Bill!P25,Bill!#REF!) -> #REF!
AB20: Arrears Received | AC20: =IF(AN14="","",AN14) -> 0 | AD20: Arrears Received | AE20: 0 | AO20: =AN17-AN16 -> 0
AB21: Total Taxable Income | AC21: =SUM(AC19:AC20) -> 0 | AD21: Total Taxable Income | AE21: =SUM(AE19:AE20) -> 0 | AL21: Tax Relief | AM21: =IF(U61=0,"No Tax Relief",U61) -> No Tax Relief
AB22: Up to Rs. 5,00,000 | AC22: 0 | AD22: Up to Rs. 2,50,000 | AE22: 0
AB23: Rs.2,50,001 To 5,00,000. (@ 5%) | AC23: =IF(AH23>0,AH23,0)*5% -> 0 | AD23: Rs.2,50,001 To 5,00,000. (@ 5%) | AE23: =IF(AJ23>0,AJ23,0)*5% -> 0 | AG23: =AC21-250000 -> -250000 | AH23: =IF(AG23>250000,250000,AG23) -> -250000 | AI23: =AE21-250000 -> -250000 | AJ23: =IF(AI23>250000,250000,AI23) -> -250000 | AM23: For result See in Anex-II, Serial No-20
C24: d. | D24: Payment in commutation of pension in accordance with the provisions of sub-rule (5) of rule 21A | S24: Rs. | T24: Not Applicable | AB24: Rs.5,00,001 To 10,00,000. (@ 20%) | AC24: =IF(AH24>0,AH24,0)*20% -> 0 | AD24: Rs.5,00,001 To 10,00,000. (@ 20%) | AE24: =IF(AJ24>0,AJ24,0)*20% -> 0 | AG24: =AC21-500000 -> -500000 | AH24: =IF(AG24>500000,500000,AG24) -> -500000 | AI24: =AE21-500000 -> -500000 | AJ24: =IF(AI24>500000,500000,AI24) -> -500000 | AM24: See in Form-16 Back,Serial No-19
AB25: above Rs.10,00,001. (@ 30%) | AC25: =IF(AH25>0,AH25,0)*30% -> 0 | AD25: above Rs.10,00,001. (@ 30%) | AE25: =IF(AJ25>0,AJ25,0)*30% -> 0 | AG25: =AC21-1000000 -> -1000000 | AH25: =IF(AG25>500000,500000,AG25) -> -1000000 | AI25: =AE21-1000000 -> -1000000 | AJ25: =IF(AI25>500000,500000,AI25) -> -1000000 | AM25: Print this page and add with Form-16
AB26: Tax rebate U/s 87A | AC26: =IF(AC21>350000,0,2500) -> 2500 | AD26: Tax rebate U/s 87A | AE26: =IF(AC19>350000,0,2500) -> 2500
B27: 2 | D27: Detailed particulars of payments refered to above may be given in Annexure-I, II, IIA, III, or IV, as the case may be | T27: Annexure-I | AB27: Total | AC27: =IF((SUM(AC22:AC25)-AC26)>0,(SUM(AC22:AC25)-AC26),0) -> 0 | AD27: Total | AE27: =IF((SUM(AE22:AE25)-AE26)>0,(SUM(AE22:AE25)-AE26),0) -> 0
AB28: Education Cess @ 1% | AC28: =ROUND(AC27*1%,0.1) -> 0 | AD28: Education Cess @ 1% | AE28: =ROUND(AE27*1%,0.1) -> 0
AB29: Secondary & Higher Education Cess @ 2% | AC29: =ROUND(AC27*2%,0.1) -> 0 | AD29: Secondary & Higher Education Cess @ 2% | AE29: =ROUND(AE27*2%,0.1) -> 0
P31: Signature of the employee | AB31: Total Tax | AC31: =SUM(AC27:AC30) -> 0 | AD31: Total Tax | AE31: =SUM(AE27:AE30) -> 0 | AF31: =AC31-AE31 -> 0
B32: Verification
AB33: Detail | AC33: 2020-21 | AD33: Detail | AE33: 2020-21
C34: =CONCATENATE(" I ",DATA!BN172," ",DATA!E10," do here by declare that what is stated above is true to the best of my knowledge and belief.") -> I Sri. A.Nagesh do here by declare that what is stated above is true to the best of my knowledge and belief. | AF34: |
AB35: Net Taxable Income | AC35: =IF(AM17="","",AM17) | AD35: Net Taxable Income | AE35: =AC35
AB36: Arrears Received | AC36: =IF(AN17="","",AN17) | AD36: Arrears Received | AE36: 0
AB37: Total Taxable Income | AC37: =SUM(AC35:AC36) -> 0 | AD37: Total Taxable Income | AE37: =SUM(AE35:AE36) -> 0
B38: Verified today : | F38: =TODAY() -> 44553 | AB38: Up to Rs. 2,50,000 | AC38: 0 | AD38: Up to Rs. 2,50,000 | AE38: 0
AB39: Rs.2,50,001 To 5,00,000. (@ 5%) | AC39: =IF(AH39>0,AH39,0)*5% -> 0 | AD39: Rs.2,50,001 To 5,00,000. (@ 10%) | AE39: =IF(AJ39>0,AJ39,0)*5% -> 0 | AG39: =AC37-250000 -> -250000 | AH39: =IF(AG39>250000,250000,AG39) -> -250000 | AI39: =AE37-250000 -> -250000 | AJ39: =IF(AI39>250000,250000,AI39) -> -250000
AB40: Rs.5,00,001 To 10,00,000. (@ 20%) | AC40: =IF(AH40>0,AH40,0)*20% -> 0 | AD40: Rs.5,00,001 To 10,00,000. (@ 20%) | AE40: =IF(AJ40>0,AJ40,0)*20% -> 0 | AG40: =AC37-500000 -> -500000 | AH40: =IF(AG40>500000,500000,AG40) -> -500000 | AI40: =AE37-500000 -> -500000 | AJ40: =IF(AI40>500000,500000,AI40) -> -500000
B41: Place : | D41: =DATA!E21 -> Velgode | AB41: above Rs.10,00,001. (@ 30%) | AC41: =IF(AH41>0,AH41,0)*30% -> 0 | AD41: above Rs.10,00,001. (@ 30%) | AE41: =IF(AJ41>0,AJ41,0)*30% -> 0 | AG41: =AC37-1000000 -> -1000000 | AH41: =IF(AG41>500000,500000,AG41) -> -1000000 | AI41: =AE37-1000000 -> -1000000 | AJ41: =IF(AI41>500000,500000,AI41) -> -1000000
B42: Date : | D42: =TODAY() -> 44553 | P42: Signature of the employee | AB42: Tax rebate U/s 87A | AC42: =IF(AC37>500000,0,12500) -> 12500 | AD42: Tax rebate U/s 87A | AE42: =IF(AE37>500000,0,12500) -> 12500
AB43: Total | AC43: =IF((SUM(AC38:AC41)-AC42)>0,(SUM(AC38:AC41)-AC42),0) -> 0 | AD43: Total | AE43: =IF((SUM(AE38:AE41)-AE42)>0,(SUM(AE38:AE41)-AE42),0) -> 0
...

Sheet DA Table
B2: =IF(DATA!CL$274=1,"AP New DA Arrears Calculator","TS New DA Arrears Calculator") -> AP New DA Arrears Calculator
B5: Basic Pay on Jan 2022
B6: Increament Month ( After Jan 2022 )
B7: Are You Taken AAS (6/12/18/24 Years) Before Dec 2020
B8: Are You Taken Promotion (07/18 to 12/20) Before Dec 20
B9: If You Taken Surrender Leave (07/2018 to 12/2020)
B10: Select CPS / PF
B11: Select HRA %
B13: =IF(DATA!CL$274=1,"AP Teachers & Employees July 2018 - 30.392% ","TS Teachers & Employees July 2019 - 38.776% ") -> AP Teachers & Employees July 2018 - 30.392%
B15: Month & Year | C15: Basic Pay | D15: Eligible DA | E15: Already Drawn DA | F15: DA Defference | G15: =IF(V190=T154,"CPS Adjustment 10%","PF Adjustment") -> PF Adjustment | H15: =IF(V190=T154,"CPS Cash 90%","PF Cash") -> PF Cash
B16: =IF(DATA!CL$274=1,"July 2018 DA","Jan 2019 DA") -> July 2018 DA | D16: =IF(DATA!CL$274=1,"30.392%","38.776%") -> 30.392% | E16: =IF(DATA!CL$274=1,"27.248%","33.536%") -> 27.248% | F16: =D16-E16 -> 0.03144 | G16: www.teacherNews.in
B17: =IF(DATA!CL$274=1,M154,"") -> 43282 | C17: =IF(B17="","",Z198) -> 19500 | D17: =IF(B17="","",ROUND(C17*D$16,0)) -> 5926 | E17: =IF(B17="","",ROUND(C17*E$16,0)) -> 5313 | F17: =IF(B17="","",(D17-E17)) -> 613 | G17: =IF(V$190=T$154,ROUND(F17*10%,0),F17) -> 613 | H17: =IF(B17="","",(IF(V$190=T$154,ROUND(F17*90%,0),0))) -> 0
B18: =IF(DATA!CL$274=1,M155,"") -> 43313 | C18: =IF(B18="","",Z199) -> 20050 | D18: =IF(B18="","",ROUND(C18*D$16,0)) -> 6094 | E18: =IF(B18="","",ROUND(C18*E$16,0)) -> 5463 | F18: =IF(B18="","",(D18-E18)) -> 631 | G18: =IF(V$190=T$154,ROUND(F18*10%,0),F18) -> 631 | H18: =IF(B18="","",(IF(V$190=T$154,ROUND(F18*90%,0),0))) -> 0
B19: =IF(DATA!CL$274=1,M156,"") -> 43344 | C19: =IF(B19="","",Z200) -> 20050 | D19: =IF(B19="","",ROUND(C19*D$16,0)) -> 6094 | E19: =IF(B19="","",ROUND(C19*E$16,0)) -> 5463 | F19: =IF(B19="","",(D19-E19)) -> 631 | G19: =IF(V$190=T$154,ROUND(F19*10%,0),F19) -> 631 | H19: =IF(B19="","",(IF(V$190=T$154,ROUND(F19*90%,0),0))) -> 0
B20: =IF(DATA!CL$274=1,M157,"") -> 43374 | C20: =IF(B20="","",Z201) -> 20050 | D20: =IF(B20="","",ROUND(C20*D$16,0)) -> 6094 | E20: =IF(B20="","",ROUND(C20*E$16,0)) -> 5463 | F20: =IF(B20="","",(D20-E20)) -> 631 | G20: =IF(V$190=T$154,ROUND(F20*10%,0),F20) -> 631 | H20: =IF(B20="","",(IF(V$190=T$154,ROUND(F20*90%,0),0))) -> 0
B21: =IF(DATA!CL$274=1,M158,"") -> 43405 | C21: =IF(B21="","",Z202) -> 20050 | D21: =IF(B21="","",ROUND(C21*D$16,0)) -> 6094 | E21: =IF(B21="","",ROUND(C21*E$16,0)) -> 5463 | F21: =IF(B21="","",(D21-E21)) -> 631 | G21: =IF(V$190=T$154,ROUND(F21*10%,0),F21) -> 631 | H21: =IF(B21="","",(IF(V$190=T$154,ROUND(F21*90%,0),0))) -> 0
B22: =IF(DATA!CL$274=1,M159,"") -> 43435 | C22: =IF(B22="","",Z203) -> 20050 | D22: =IF(B22="","",ROUND(C22*D$16,0)) -> 6094 | E22: =IF(B22="","",ROUND(C22*E$16,0)) -> 5463 | F22: =IF(B22="","",(D22-E22)) -> 631 | G22: =IF(V$190=T$154,ROUND(F22*10%,0),F22) -> 631 | H22: =IF(B22="","",(IF(V$190=T$154,ROUND(F22*90%,0),0))) -> 0
B23: =IF(DATA!CL$274=1,M160,"") -> 43466 | C23: =IF(B23="","",Z204) -> 20050 | D23: =IF(B23="","",ROUND(C23*D$16,0)) -> 6094 | E23: =IF(B23="","",ROUND(C23*E$16,0)) -> 5463 | F23: =IF(B23="","",(D23-E23)) -> 631 | G23: =IF(V$190=T$154,ROUND(F23*10%,0),F23) -> 631 | H23: =IF(B23="","",(IF(V$190=T$154,ROUND(F23*90%,0),0))) -> 0
B24: =IF(DATA!CL$274=1,M161,"") -> 43497 | C24: =IF(B24="","",Z205) -> 20050 | D24: =IF(B24="","",ROUND(C24*D$16,0)) -> 6094 | E24: =IF(B24="","",ROUND(C24*E$16,0)) -> 5463 | F24: =IF(B24="","",(D24-E24)) -> 631 | G24: =IF(V$190=T$154,ROUND(F24*10%,0),F24) -> 631 | H24: =IF(B24="","",(IF(V$190=T$154,ROUND(F24*90%,0),0))) -> 0
B25: =IF(DATA!CL$274=1,M162,"") -> 43525 | C25: =IF(B25="","",Z206) -> 20050 | D25: =IF(B25="","",ROUND(C25*D$16,0)) -> 6094 | E25: =IF(B25="","",ROUND(C25*E$16,0)) -> 5463 | F25: =IF(B25="","",(D25-E25)) -> 631 | G25: =IF(V$190=T$154,ROUND(F25*10%,0),F25) -> 631 | H25: =IF(B25="","",(IF(V$190=T$154,ROUND(F25*90%,0),0))) -> 0
B26: =IF(DATA!CL$274=1,M163,"") -> 43556 | C26: =IF(B26="","",Z207) -> 20050 | D26: =IF(B26="","",ROUND(C26*D$16,0)) -> 6094 | E26: =IF(B26="","",ROUND(C26*E$16,0)) -> 5463 | F26: =IF(B26="","",(D26-E26)) -> 631 | G26: =IF(V$190=T$154,ROUND(F26*10%,0),F26) -> 631 | H26: =IF(B26="","",(IF(V$190=T$154,ROUND(F26*90%,0),0))) -> 0
B27: =IF(DATA!CL$274=1,M164,"") -> 43586 | C27: =IF(B27="","",Z208) -> 20050 | D27: =IF(B27="","",ROUND(C27*D$16,0)) -> 6094 | E27: =IF(B27="","",ROUND(C27*E$16,0)) -> 5463 | F27: =IF(B27="","",(D27-E27)) -> 631 | G27: =IF(V$190=T$154,ROUND(F27*10%,0),F27) -> 631 | H27: =IF(B27="","",(IF(V$190=T$154,ROUND(F27*90%,0),0))) -> 0
B28: =IF(DATA!CL$274=1,M165,"") -> 43617 | C28: =IF(B28="","",Z209) -> 20050 | D28: =IF(B28="","",ROUND(C28*D$16,0)) -> 6094 | E28: =IF(B28="","",ROUND(C28*E$16,0)) -> 5463 | F28: =IF(B28="","",(D28-E28)) -> 631 | G28: =IF(V$190=T$154,ROUND(F28*10%,0),F28) -> 631 | H28: =IF(B28="","",(IF(V$190=T$154,ROUND(F28*90%,0),0))) -> 0
B29: 43647 | C29: =Z210 -> 20050 | D29: =ROUND(C29*D$16,0) -> 6094 | E29: =ROUND(C29*E$16,0) -> 5463 | F29: =D29-E29 -> 631 | G29: =IF(V$190=T$154,ROUND(F29*10%,0),F29) -> 631 | H29: =IF(V$190=T$154,ROUND(F29*90%,0),0) -> 0
B30: 43678 | C30: =Z211 -> 20640 | D30: =ROUND(C30*D$16,0) -> 6273 | E30: =ROUND(C30*E$16,0) -> 5624 | F30: =D30-E30 -> 649 | G30: =IF(V$190=T$154,ROUND(F30*10%,0),F30) -> 649 | H30: =IF(V$190=T$154,ROUND(F30*90%,0),0) -> 0
B31: 43709 | C31: =Z212 -> 20640 | D31: =ROUND(C31*D$16,0) -> 6273 | E31: =ROUND(C31*E$16,0) -> 5624 | F31: =D31-E31 -> 649 | G31: =IF(V$190=T$154,ROUND(F31*10%,0),F31) -> 649 | H31: =IF(V$190=T$154,ROUND(F31*90%,0),0) -> 0
B32: 43739 | C32: =Z213 -> 20640 | D32: =ROUND(C32*D$16,0) -> 6273 | E32: =ROUND(C32*E$16,0) -> 5624 | F32: =D32-E32 -> 649 | G32: =IF(V$190=T$154,ROUND(F32*10%,0),F32) -> 649 | H32: =IF(V$190=T$154,ROUND(F32*90%,0),0) -> 0
B33: 43770 | C33: =Z214 -> 20640 | D33: =ROUND(C33*D$16,0) -> 6273 | E33: =ROUND(C33*E$16,0) -> 5624 | F33: =D33-E33 -> 649 | G33: =IF(V$190=T$154,ROUND(F33*10%,0),F33) -> 649 | H33: =IF(V$190=T$154,ROUND(F33*90%,0),0) -> 0
B34: 43800 | C34: =Z215 -> 20640 | D34: =ROUND(C34*D$16,0) -> 6273 | E34: =ROUND(C34*E$16,0) -> 5624 | F34: =D34-E34 -> 649 | G34: =IF(V$190=T$154,ROUND(F34*10%,0),F34) -> 649 | H34: =IF(V$190=T$154,ROUND(F34*90%,0),0) -> 0
B35: 43831 | C35: =Z216 -> 20640 | D35: =ROUND(C35*D$16,0) -> 6273 | E35: =ROUND(C35*E$16,0) -> 5624 | F35: =D35-E35 -> 649 | G35: =IF(V$190=T$154,ROUND(F35*10%,0),F35) -> 649 | H35: =IF(V$190=T$154,ROUND(F35*90%,0),0) -> 0
B36: 43862 | C36: =Z217 -> 20640 | D36: =ROUND(C36*D$16,0) -> 6273 | E36: =ROUND(C36*E$16,0) -> 5624 | F36: =D36-E36 -> 649 | G36: =IF(V$190=T$154,ROUND(F36*10%,0),F36) -> 649 | H36: =IF(V$190=T$154,ROUND(F36*90%,0),0) -> 0
